Workbook

Sheet Check List
B2: CLIENTE
B3: CHECK LIST
B5: PROYECTO DE INVERSION
E7: Presentacion / Curriculum de la empresa
E9: Resumen ejecutivo
E11: Proyecciones financieras
E13: Cuadro descriptivo de la estructura directiva
E15: CV de los principales directivos y socios
B17: LEGAL
E19: Acta Constitutiva
E21: Poderes y Asambleas
B23: FINANCIERA
C25: Estados Financieros (Estados de Resultados, Balance General, Relaciones Analiticas)
E27: Estados Financieros 2019
E29: Estados Financieros 2020
E31: Estado Financieroa Parcial 2021
E33: Estados de cuenta banacarios de los ultimos 12 meses
E35: Proyecciones Financieras del proyecto
B37: FISCAL
E39: Constancia de Situacion Fiscal
E41: Declaración anual 2019
E43: Declaración Anual 2020
E45: Ultimas 3 declaraciones provisionales
E47: Comprobante de domicilio Fiscal
B49: BURO DE CREDITO
E51: Reporte de buro de credito Especial PM
E53: Reporte buró de crédito Especial Socios accionistas y/o RL

Sheet Infromacion General 
C2: ='Check List'!B2 -> CLIENTE
C3: Información General
B5: DATOS GENERALES
E6: Razon Social:
E7: Nombre Comercial: | F7: =C2 -> CLIENTE
E8: RFC: | J8: Domicilio Fiscal:
E9: Ciudad: | L9: Estado:
E10: Contacto | M10: Telefono:
E11: Correo electrónico: | N11: Pagina web:
E12: Numero de empleados: | G12: Permanentes: | J12: Eventuales:
B14: HISTORIA Y DESCRIPCIÓN DEL CLIENTE
B18: CUANDRO ACCIONARIO | M18: PRINCIPALES FUNCIONARIOS
B20: # | C20: Nombre | H20: % | I20: $ | M20: Nombre | Q20: Puesto / Funcion
B21: 1
B22: 2
B23: 3
B24: 4
B25: 5
B26: 6
B28: SOLICITUD
E29: Monto:
E30: Divisa:
E31: Plazo deseado:
E32: Destino:
E33: Tasa Objetivo:
E34: Tipo de Colateral:
B36: INFORMACION CUANTITATIVA
E37: Nivel de Ventas Anuales: | J37: Margen Real de Utilidad: | O37: Situación de Buró de Credito:
B39: PRICIPALES CLIENTES | M39: PRINCIPALES PROVEEDORES
B41: Nombre | I41: Dias | M41: Nnombre | R41: Dias
B47: PRINCIPALES COMPETIDORES
B48: Nombre | I48: Mayor / Menor
B54: RELACION PATRIMONIAL
B56: Propietario | G56: Tipo de Propiedad | J56: Domicilio | O56: Mts 2 Terreno | P56: Mts2 Constuccion | Q56: Valor Estimado | S56: Gravamen | T56: Propuesta | AE56: Saldo deudor del objeto del gravamen
Q63: =SUM(Q57:R62) -> 0

Sheet Flujos
B2: CUENTAS EN PESOS
D4: BANCO XXXX | H4: BANCO XXX | L4: BANCO XXXX | P4: TOTALES PESOS
B5: Año | C5: Mes | D5: Ingresos | E5: Egresos | F5: Saldos Promedio | H5: Ingresos | I5: Egresos | J5: Saldos Promedio | L5: Ingresos | M5: Egresos | N5: Saldos Promedio | P5: Ingresos | Q5: Egresos | R5: Saldos Promedio
B6: 2020 | C6: Enero | J6: 0 | N6: 0 | P6: =D6+H6+L6 -> 0 | Q6: =E6+I6+M6 -> 0 | R6: =F6+J6+N6 -> 0
B7: 2020 | C7: Febrero | P7: =D7+H7+L7 -> 0 | Q7: =E7+I7+M7 -> 0 | R7: =F7+J7+N7 -> 0
B8: 2020 | C8: Marzo | P8: =D8+H8+L8 -> 0 | Q8: =E8+I8+M8 -> 0 | R8: =F8+J8+N8 -> 0
B9: 2020 | C9: Abril | P9: =D9+H9+L9 -> 0 | Q9: =E9+I9+M9 -> 0 | R9: =F9+J9+N9 -> 0
B10: 2020 | C10: Mayo | P10: =D10+H10+L10 -> 0 | Q10: =E10+I10+M10 -> 0 | R10: =F10+J10+N10 -> 0
B11: 2020 | C11: Junio | P11: =D11+H11+L11 -> 0 | Q11: =E11+I11+M11 -> 0 | R11: =F11+J11+N11 -> 0
B12: 2020 | C12: Julio | P12: =D12+H12+L12 -> 0 | Q12: =E12+I12+M12 -> 0 | R12: =F12+J12+N12 -> 0
B13: 2020 | C13: Agosto | P13: =D13+H13+L13 -> 0 | Q13: =E13+I13+M13 -> 0 | R13: =F13+J13+N13 -> 0
B14: 2020 | C14: Septiembre | P14: =D14+H14+L14 -> 0 | Q14: =E14+I14+M14 -> 0 | R14: =F14+J14+N14 -> 0
B15: 2020 | C15: Octubre | P15: =D15+H15+L15 -> 0 | Q15: =E15+I15+M15 -> 0 | R15: =F15+J15+N15 -> 0
B16: 2020 | C16: Noviembre | P16: =D16+H16+L16 -> 0 | Q16: =E16+I16+M16 -> 0 | R16: =F16+J16+N16 -> 0
B17: 2020 | C17: Diciembre | P17: =D17+H17+L17 -> 0 | Q17: =E17+I17+M17 -> 0 | R17: =F17+J17+N17 -> 0
B18: TOTALES | D18: =SUM(D6:D17) -> 0 | E18: =SUM(E6:E17) -> 0 | F18: =AVERAGE(F6:F17) -> #DIV/0! | H18: =SUM(H6:H17) -> 0 | I18: =SUM(I6:I17) -> 0 | J18: =AVERAGE(J6:J17) -> 0 | L18: =SUM(L6:L17) -> 0 | M18: =SUM(M6:M17) -> 0 | N18: =AVERAGE(N6:N17) -> 0 | P18: =SUM(P6:P17) -> 0 | Q18: =SUM(Q6:Q17) -> 0 | R18: =SUM(R6:R17) -> 0
B20: CUENTAS EN DOLARES
D22: BANCO CTA. XXX | H22: BANCO CTA. XXX | L22: BANCO CTA. XXX | P22: TOTALES DOLARES
B23: Año | C23: Mes | D23: Ingresos | E23: Egresos | F23: Saldos Promedio | H23: Ingresos | I23: Egresos | J23: Saldos Promedio | L23: Ingresos | M23: Egresos | N23: Saldos Promedio | P23: Ingresos | Q23: Egresos | R23: Saldos Promedio
B24: =B6 -> 2020 | C24: =C6 -> Enero | P24: =D24+H24+L24 -> 0 | Q24: =E24+I24+M24 -> 0 | R24: =F24+J24+N24 -> 0
B25: =B7 -> 2020 | C25: =C7 -> Febrero | P25: =D25+H25+L25 -> 0 | Q25: =E25+I25+M25 -> 0 | R25: =F25+J25+N25 -> 0
B26: =B8 -> 2020 | C26: =C8 -> Marzo | P26: =D26+H26+L26 -> 0 | Q26: =E26+I26+M26 -> 0 | R26: =F26+J26+N26 -> 0
B27: =B9 -> 2020 | C27: =C9 -> Abril | P27: =D27+H27+L27 -> 0 | Q27: =E27+I27+M27 -> 0 | R27: =F27+J27+N27 -> 0
B28: =B10 -> 2020 | C28: =C10 -> Mayo | P28: =D28+H28+L28 -> 0 | Q28: =E28+I28+M28 -> 0 | R28: =F28+J28+N28 -> 0
B29: =B11 -> 2020 | C29: =C11 -> Junio | P29: =D29+H29+L29 -> 0 | Q29: =E29+I29+M29 -> 0 | R29: =F29+J29+N29 -> 0
B30: =B12 -> 2020 | C30: =C12 -> Julio | P30: =D30+H30+L30 -> 0 | Q30: =E30+I30+M30 -> 0 | R30: =F30+J30+N30 -> 0
B31: =B13 -> 2020 | C31: =C13 -> Agosto | P31: =D31+H31+L31 -> 0 | Q31: =E31+I31+M31 -> 0 | R31: =F31+J31+N31 -> 0
B32: =B14 -> 2020 | C32: =C14 -> Septiembre | P32: =D32+H32+L32 -> 0 | Q32: =E32+I32+M32 -> 0 | R32: =F32+J32+N32 -> 0
B33: =B15 -> 2020 | C33: =C15 -> Octubre | P33: =D33+H33+L33 -> 0 | Q33: =E33+I33+M33 -> 0 | R33: =F33+J33+N33 -> 0
B34: =B16 -> 2020 | C34: =C16 -> Noviembre | P34: =D34+H34+L34 -> 0 | Q34: =E34+I34+M34 -> 0 | R34: =F34+J34+N34 -> 0
B35: =B17 -> 2020 | C35: =C17 -> Diciembre | P35: =D35+H35+L35 -> 0 | Q35: =E35+I35+M35 -> 0 | R35: =F35+J35+N35 -> 0
B36: TOTALES | D36: =SUM(D24:D35) -> 0 | E36: =SUM(E24:E35) -> 0 | F36: =AVERAGE(F24:F35) -> #DIV/0! | H36: =SUM(H24:H35) -> 0 | I36: =SUM(I24:I35) -> 0 | J36: =AVERAGE(J24:J35) -> #DIV/0! | L36: =SUM(L24:L35) -> 0 | M36: =SUM(M24:M35) -> 0 | N36: =AVERAGE(N24:N35) -> #DIV/0! | P36: =SUM(P24:P35) -> 0 | Q36: =SUM(Q24:Q35) -> 0 | R36: =F36+J36+N36 -> #DIV/0!
B38: TOTAL GENERAL
D41: CONVERSION USD A MX
D42: PESOS X DÓLAR: | F42: 1 | H42: TOTAL CUENTAS PESOS | L42: TOTAL GENERAL
B43: Año | C43: Mes | D43: Ingresos | E43: Egresos | F43: Saldo Promedio | H43: Ingresos | I43: Egresos | J43: Saldo Promedio | L43: Ingresos | M43: Egresos | N43: Saldo Promedio
B44: =B6 -> 2020 | C44: =C6 -> Enero | D44: =P24*$F$42 -> 0 | E44: =Q24*$F$42 -> 0 | F44: =R24*$F$42 -> 0 | H44: =P6 -> 0 | I44: =Q6 -> 0 | J44: =R6 -> 0 | L44: =D44+H44 -> 0 | M44: =E44+I44 -> 0 | N44: =F44+J44 -> 0
B45: =B7 -> 2020 | C45: =C7 -> Febrero | D45: =P25*$F$42 -> 0 | E45: =Q25*$F$42 -> 0 | F45: =R25*$F$42 -> 0 | H45: =P7 -> 0 | I45: =Q7 -> 0 | J45: =R7 -> 0 | L45: =D45+H45 -> 0 | M45: =E45+I45 -> 0 | N45: =F45+J45 -> 0
B46: =B8 -> 2020 | C46: =C8 -> Marzo | D46: =P26*$F$42 -> 0 | E46: =Q26*$F$42 -> 0 | F46: =R26*$F$42 -> 0 | H46: =P8 -> 0 | I46: =Q8 -> 0 | J46: =R8 -> 0 | L46: =D46+H46 -> 0 | M46: =E46+I46 -> 0 | N46: =F46+J46 -> 0
B47: =B9 -> 2020 | C47: =C9 -> Abril | D47: =P27*$F$42 -> 0 | E47: =Q27*$F$42 -> 0 | F47: =R27*$F$42 -> 0 | H47: =P9 -> 0 | I47: =Q9 -> 0 | J47: =R9 -> 0 | L47: =D47+H47 -> 0 | M47: =E47+I47 -> 0 | N47: =F47+J47 -> 0
...

Sheet Estados Financieros
M3: ='Infromacion General '!C2 -> CLIENTE
J4: Parametrox
L5: ='Infromacion General '!F29/1000 -> 0
B6: BALANCE GENERAL | J6: COMPORTAMIENTO GRAFICO
G7: =MONTH(G8) -> 6
C8: 43830 | E8: 44196 | G8: 44377 | K8: =C8 -> 43830 | L8: =E8 -> 44196 | M8: =G8 -> 44377
C9: $ | D9: % | E9: $ | F9: % | G9: $ | H9: % | J9: =B10 -> Activo Circulante | K9: =C10 -> 0 | L9: =E10 -> 0 | M9: =G10 -> 0
B10: Activo Circulante | J10: =B14 -> Activo Fijo | K10: =C14 -> 0 | L10: =E14 -> 0 | M10: =G14 -> 0
B11: Inventarios | D11: =C11/C10 -> #DIV/0! | F11: =E11/E10 -> #DIV/0! | H11: =G11/G10 -> #DIV/0! | J11: =B18 -> Otros Activos | K11: =C18 -> 0 | L11: =E18 -> 0 | M11: =G18 -> 0
B12: Clientes | D12: =C12/C10 -> #DIV/0! | F12: =E12/E10 -> #DIV/0! | H12: =G12/G10 -> #DIV/0! | J12: =B20 -> ACTIVO TOTAL | K12: =C20 -> 0 | L12: =E20 -> 0 | M12: =G20 -> 0
B13: Deudores Diversos | D13: =C13/C10 -> #DIV/0! | F13: =E13/E10 -> #DIV/0! | H13: =G13/G10 -> #DIV/0!
B14: Activo Fijo
B15: Terrenos y Edificios | D15: =C15/C14 -> #DIV/0! | F15: =E15/E14 -> #DIV/0! | H15: =G15/G14 -> #DIV/0!
B16: Maquinaria y Equipo | D16: =C16/C14 -> #DIV/0! | F16: =E16/E14 -> #DIV/0! | H16: =G16/G14 -> #DIV/0!
B17: Equipo de Transporte | D17: =C17/C14 -> #DIV/0! | F17: =E17/E14 -> #DIV/0! | H17: =G17/G14 -> #DIV/0!
B18: Otros Activos
B19: Intangibles (registro de marca) | D19: =C19/C18 -> #DIV/0! | F19: =E19/E18 -> #DIV/0! | H19: =G19/G18 -> #DIV/0!
B20: ACTIVO TOTAL | C20: =C10+C14+C18 -> 0 | E20: =E10+E14+E18 -> 0 | G20: =G10+G14+G18 -> 0 | K20: =C8 -> 43830 | L20: =E8 -> 44196 | M20: =G8 -> 44377
B21: Pasivo Circulante | J21: =B21 -> Pasivo Circulante | K21: =C21 -> 0 | L21: =E21 -> 0 | M21: =G21 -> 0
B22: Proveedores | D22: =C22/C21 -> #DIV/0! | F22: =E22/E21 -> #DIV/0! | H22: =G22/G21 -> #DIV/0! | J22: =B25 -> Pasivo Largo Plazo | K22: =C25 -> 0 | L22: =E25 -> 0 | M22: =G25 -> 0
B23: Acreedores Div. | D23: =C23/C21 -> #DIV/0! | F23: =E23/E21 -> #DIV/0! | H23: =G23/G21 -> #DIV/0! | J23: =B28 -> PASIVO TOTAL | K23: =C28 -> 0 | L23: =E28 -> 0 | M23: =G28 -> 0
B24: Docs. x pagar CP | D24: =C24/C21 -> #DIV/0! | F24: =E24/E21 -> #DIV/0! | H24: =G24/G21 -> #DIV/0!
B25: Pasivo Largo Plazo
B26: Docs. X pagar LP | D26: =C26/C25 -> #DIV/0! | F26: =E26/E25 -> #DIV/0! | H26: =G26/G25 -> #DIV/0!
B27: Otros Pasivos
B28: PASIVO TOTAL | C28: =C21+C25+C27 -> 0 | E28: =E21+E25+E27 -> 0 | G28: =G21+G25+G27 -> 0
B29: Capital Social | D29: =C29/C31 -> #DIV/0! | F29: =E29/E31 -> #DIV/0! | H29: =G29/G31 -> #DIV/0!
B30: Ut Ejercicios anterioes | D30: =C30/C31 -> #DIV/0! | F30: =E30/E31 -> #DIV/0! | H30: =G30/G31 -> #DIV/0!
B31: Capital Contable
B33: Estado de Resultados
B34: VENTAS | D34: 1 | F34: 1 | H34: 1 | K34: =C8 -> 43830 | L34: =E8 -> 44196 | M34: =G8 -> 44377
B35: Costos de Venta | D35: =C35/$C$34 -> #DIV/0! | F35: =E35/$E$34 -> #DIV/0! | H35: =G35/$G$34 -> #DIV/0!
B36: Ut. Bruta | C36: =C34-C35 -> 0 | D36: =C36/$C$34 -> #DIV/0! | E36: =E34-E35 -> 0 | F36: =E36/$E$34 -> #DIV/0! | G36: =G34-G35 -> 0 | H36: =G36/$G$34 -> #DIV/0! | J36: =B35 -> Costos de Venta | K36: =C35 -> 0 | L36: =E35 -> 0 | M36: =G35 -> 0
B37: Gastos de Op. | D37: =C37/$C$34 -> #DIV/0! | F37: =E37/$E$34 -> #DIV/0! | H37: =G37/$G$34 -> #DIV/0! | J37: =B37 -> Gastos de Op. | K37: =C37 -> 0 | L37: =E37 -> 0 | M37: =G37 -> 0
B38: UT. De operación | C38: =C36-C37 -> 0 | D38: =C38/$C$34 -> #DIV/0! | E38: =E36-E37 -> 0 | F38: =E38/$E$34 -> #DIV/0! | G38: =G36-G37 -> 0 | H38: =G38/$G$34 -> #DIV/0! | J38: =B43 -> Impuestos | K38: =C43 -> 0 | L38: =E43 -> 0 | M38: =G43 -> 0
B39: Gastos Fin. | D39: =C39/$C$34 -> #DIV/0! | F39: =E39/$E$34 -> #DIV/0! | H39: =G39/$G$34 -> #DIV/0! | J39: =B44 -> Depreciacion | K39: =C44 -> 0 | L39: =E44 -> 0 | M39: =G44 -> 0
B40: Otros productos | D40: =C40/$C$34 -> #DIV/0! | F40: =E40/$E$34 -> #DIV/0! | H40: =G40/$G$34 -> #DIV/0! | J40: =B45 -> UTILIDAD NETA | K40: =C45 -> 0 | L40: =E45 -> 0 | M40: =G45 -> 0
B41: Otros Gastos | D41: =C41/$C$34 -> #DIV/0! | F41: =E41/$E$34 -> #DIV/0! | H41: =G41/$G$34 -> #DIV/0!
B42: UT. Antes de impuestos | C42: =C38-C39+C40-C41 -> 0 | D42: =C42/$C$34 -> #DIV/0! | E42: =E38-E39+E40-E41 -> 0 | F42: =E42/$E$34 -> #DIV/0! | G42: =G38-G39+G40-G41 -> 0 | H42: =G42/$G$34 -> #DIV/0!
B43: Impuestos | D43: =C43/$C$34 -> #DIV/0! | F43: =E43/$E$34 -> #DIV/0! | H43: =G43/$G$34 -> #DIV/0!
...

Sheet Hoja1
B2: RAZONES | H2: GRAFICO DE RAZONES
C4: ='Estados Financieros'!C8 -> 43830 | D4: ='Estados Financieros'!E8 -> 44196 | E4: ='Estados Financieros'!G8 -> 44377
B5: Razón | F5: FORMULAS
B6: De Liquidez
B7: Circulante / Liquidez | C7: ='Estados Financieros'!C10/'Estados Financieros'!C21 -> #DIV/0! | D7: ='Estados Financieros'!E10/'Estados Financieros'!E21 -> #DIV/0! | E7: ='Estados Financieros'!G10/'Estados Financieros'!G21 -> #DIV/0! | F7: Activo Circulante / Pasivo Circulante
B8: Prueba del Acido | C8: =('Estados Financieros'!C10-'Estados Financieros'!C11)/'Estados Financieros'!C21 -> #DIV/0! | D8: =('Estados Financieros'!E10-'Estados Financieros'!E11)/'Estados Financieros'!E21 -> #DIV/0! | E8: =('Estados Financieros'!G10-'Estados Financieros'!G11)/'Estados Financieros'!G21 -> #DIV/0! | F8: (Activo Circulante - Inventarios)/ Pasivo Circulante
B9: De Actividad o Uso de Activos
B10: Rotación de Cuentas X Cobrar | C10: =365/('Estados Financieros'!C34/'Estados Financieros'!C12) -> #DIV/0! | D10: =365/('Estados Financieros'!E34/'Estados Financieros'!E12) -> #DIV/0! | E10: =('Estados Financieros'!G7*30)/('Estados Financieros'!G34/'Estados Financieros'!G12) -> #DIV/0! | F10: 365 / (Ventas / Clientes)
B11: Rotación de Cuentas x Pagar | C11: =('Estados Financieros'!C22/'Estados Financieros'!C35)*365 -> #DIV/0! | D11: =('Estados Financieros'!E22/'Estados Financieros'!E35)*365 -> #DIV/0! | E11: =('Estados Financieros'!G22/'Estados Financieros'!G35)*('Estados Financieros'!G7*30) -> #DIV/0! | F11: (Proveedores / Costos de Venta)*365
B12: Rotación de Inventarios | C12: =('Estados Financieros'!C11/'Estados Financieros'!C35)*365 -> #DIV/0! | D12: =('Estados Financieros'!E11/'Estados Financieros'!E35)*365 -> #DIV/0! | E12: =('Estados Financieros'!G11/'Estados Financieros'!G35)*('Estados Financieros'!G7*30) -> #DIV/0! | F12: (Inventarios / Costos de Venta)*365
B13: De Apalancamiento Financiero
B14: Deuda Total | C14: ='Estados Financieros'!C28/'Estados Financieros'!C20 -> #DIV/0! | D14: ='Estados Financieros'!E28/'Estados Financieros'!E20 -> #DIV/0! | E14: ='Estados Financieros'!G28/'Estados Financieros'!G20 -> #DIV/0! | F14: Pasivo Total / Activo Total
B15: Deuda Total Despues de Financiamiento | C15: =C14 -> #DIV/0! | D15: =D14 -> #DIV/0! | E15: =('Estados Financieros'!G28+'Estados Financieros'!L5)/'Estados Financieros'!G20 -> #DIV/0!
B16: Deuda Total a Capital Contable | C16: ='Estados Financieros'!C28/'Estados Financieros'!C31 -> #DIV/0! | D16: ='Estados Financieros'!E28/'Estados Financieros'!E31 -> #DIV/0! | E16: ='Estados Financieros'!G28/'Estados Financieros'!G31 -> #DIV/0! | F16: Pasivo Total / Capital Contable
B17: Deuda a Largo Plazo | C17: ='Estados Financieros'!C25/('Estados Financieros'!C20-'Estados Financieros'!C28) -> #DIV/0! | D17: ='Estados Financieros'!E25/('Estados Financieros'!E20-'Estados Financieros'!E28) -> #DIV/0! | E17: ='Estados Financieros'!G25/('Estados Financieros'!G20-'Estados Financieros'!G28) -> #DIV/0! | F17: Pasivo Largo Plazo / (Activo Total - Pasivo Total)
B18: De Rentabilidad
B19: Margen de Utilidad | C19: ='Estados Financieros'!C45/'Estados Financieros'!C34 -> #DIV/0! | D19: ='Estados Financieros'!E45/'Estados Financieros'!E34 -> #DIV/0! | E19: ='Estados Financieros'!G45/'Estados Financieros'!G34 -> #DIV/0! | F19: Utilidad Neta / Ventas
B20: Rendimiento en Activos (ROA) | C20: ='Estados Financieros'!C45/'Estados Financieros'!C20 -> #DIV/0! | D20: ='Estados Financieros'!E45/'Estados Financieros'!E20 -> #DIV/0! | E20: ='Estados Financieros'!G45/'Estados Financieros'!G20 -> #DIV/0! | F20: Utilidad Neta / Activos Totales
B21: Rendimiento en Capital Contable (ROE) | C21: ='Estados Financieros'!C45/'Estados Financieros'!C31 -> #DIV/0! | D21: ='Estados Financieros'!E45/'Estados Financieros'!E31 -> #DIV/0! | E21: ='Estados Financieros'!G45/'Estados Financieros'!G31 -> #DIV/0! | F21: Utilidad Neta / Capital Contable
B23: RESUMEN DE FLUJOS DE EFECTIVO BANCARIOS
B25: #REF! | C25: #REF! | D25: #REF! | E25: #REF! | F25: #REF!
B26: =Flujos!B6 -> 2020 | C26: =Flujos!C6 -> Enero | D26: =Flujos!L44 -> 0 | E26: =Flujos!M44 -> 0 | F26: =Flujos!N44 -> 0
B27: =Flujos!B7 -> 2020 | C27: =Flujos!C7 -> Febrero | D27: =Flujos!L45 -> 0 | E27: =Flujos!M45 -> 0 | F27: =Flujos!N45 -> 0
B28: =Flujos!B8 -> 2020 | C28: =Flujos!C8 -> Marzo | D28: =Flujos!L46 -> 0 | E28: =Flujos!M46 -> 0 | F28: =Flujos!N46 -> 0
B29: =Flujos!B9 -> 2020 | C29: =Flujos!C9 -> Abril | D29: =Flujos!L47 -> 0 | E29: =Flujos!M47 -> 0 | F29: =Flujos!N47 -> 0
B30: =Flujos!B10 -> 2020 | C30: =Flujos!C10 -> Mayo | D30: =Flujos!L48 -> 0 | E30: =Flujos!M48 -> 0 | F30: =Flujos!N48 -> 0
B31: =Flujos!B11 -> 2020 | C31: =Flujos!C11 -> Junio | D31: =Flujos!L49 -> 0 | E31: =Flujos!M49 -> 0 | F31: =Flujos!N49 -> 0
B32: =Flujos!B12 -> 2020 | C32: =Flujos!C12 -> Julio | D32: =Flujos!L50 -> 0 | E32: =Flujos!M50 -> 0 | F32: =Flujos!N50 -> 0
B33: =Flujos!B13 -> 2020 | C33: =Flujos!C13 -> Agosto | D33: =Flujos!L51 -> 0 | E33: =Flujos!M51 -> 0 | F33: =Flujos!N51 -> 0
B34: =Flujos!B14 -> 2020 | C34: =Flujos!C14 -> Septiembre | D34: =Flujos!L52 -> 0 | E34: =Flujos!M52 -> 0 | F34: =Flujos!N52 -> 0
B35: =Flujos!B15 -> 2020 | C35: =Flujos!C15 -> Octubre | D35: =Flujos!L53 -> 0 | E35: =Flujos!M53 -> 0 | F35: =Flujos!N53 -> 0
B36: =Flujos!B16 -> 2020 | C36: =Flujos!C16 -> Noviembre | D36: =Flujos!L54 -> 0 | E36: =Flujos!M54 -> 0 | F36: =Flujos!N54 -> 0
B37: =Flujos!B17 -> 2020 | C37: =Flujos!C17 -> Diciembre | D37: =Flujos!L55 -> 0 | E37: =Flujos!M55 -> 0 | F37: =Flujos!N55 -> 0
C38: TOTAL | D38: =SUM(D26:D37) -> 0 | E38: =SUM(E26:E37) -> 0 | F38: =SUM(F26:F37) -> 0
B39: Resultados de Analisis
B41: Maximo por Capacidad Contable | C41: =(('Estados Financieros'!C31+'Estados Financieros'!C29+'Estados Financieros'!E31+'Estados Financieros'!E29)+'Estados Financieros'!C47/2)*0.25 -> #VALUE!
B42: Maximo por Ventas | C42: =('Estados Financieros'!G34/'Estados Financieros'!G7)*3 -> 0
B43: Maximo por Palanca | C43: =('Estados Financieros'!G31+'Estados Financieros'!G29-'Estados Financieros'!G28)*0.85 -> 0
B44: Maximo por Flujos | C44: =AVERAGE(D26:D37)*2 -> 0

Sheet Analisis
J1: =TODAY() -> 46084
J2: ='Check List'!B2 -> CLIENTE
J3: Análisis
B5: BURO DE CREDITO
B7: Titular | C7: Calificacion ultimo año | D7: Linea Mayor | E7: Comentarios
B8: PM
B9: RL
B10: SOCIO 1
B12: BALANCE GENERAL
B21: ESTADO DE RESULTADOS
B26: FLUJOS
B28: DECLARACION ANUAL
B31: OBSERVACIONES / CONCLUSIONES
B37: RUTAS
B39: Institucion | C39: Tipo | D39: Monto | E39: Plazo | F39: Garantia | G39: Comentarios
